Workbook

Sheet 00_Cover
C5: Nexus Technologies — Integrated Financial Model
B12: 3-Statement Model | Scenario Forecast | DCF Valuation
B14: Built from Project Atlas Gold Finance Warehouse
C17: © 2023 to 2026 Atlas Intelligence Platform
C18: Prepared by: Lewis Andrews
C19: Version: v0.1
C20: Currency: GBP
C21: Model period: Jan-2023 to Dec-2029

Sheet 01_Model_Map

Sheet 02_Control
A1: Nexus Technologies — Integrated Financial Model
A4: Control Panel
A5: ="Currency: "&B12&" | Units: "&B13&" | Version: "&B16 -> Currency: GBP | Units: £ actual | Version: v0.1
A7: Field | B7: Value
A8: Model Start Month | B8: 44927
A9: Actuals Through | B9: 46203 | L9: Scenario_List | M9: Units_List | N9: Reporting_Scope_List
A10: Forecast Start Month | B10: 46204 | L10: Base | M10: £ actual | N10: Company Total
A11: Forecast End Month | B11: 47453 | L11: Upside | M11: £000 | N11: Region Total
A12: Currency | B12: GBP | L12: Downside | M12: £m | N12: Business Unit Total
A13: Units | B13: £ actual
A14: Scenario | B14: Base
A15: Reporting Scope | B15: Company Total
A16: Model Version | B16: v0.1
A17: Last Updated | B17: =TODAY() -> 46204
A18: Unit Scale Factor | B18: {=_xlfn.SWITCH(B13,"£ actual",1,"£000",1000,"£m",1000000,1)} -> 1

Sheet 03_Raw_Exports
A1: Nexus Technologies — Raw Data Exports
A2: Source connection inventory (Power Query — Connection Only)
A3: Source Area | B3: File Name | C3: Query Name | D3: Load Type | E3: Status | F3: Notes
A4: Revenue | B4: mart_revenue_waterfall.csv | C4: src_revenue_waterfall | D4: Connection only | E4: Imported | F4: Recognition, billings, leakage
A5: O2C | B5: mart_o2c_customer_collections.csv | C5: src_o2c_customer_collections | D5: Connection only | E5: Imported | F5: Cash collected, AR exposure
A6: Deferred Revenue | B6: mart_deferred_revenue_control.csv | C6: src_deferred_revenue_control | D6: Connection only | E6: Imported | F6: Deferred revenue rollforward
A7: AP | B7: mart_ap_working_capital_control.csv | C7: src_ap_working_capital_control | D7: Connection only | E7: Imported | F7: Supplier spend, payments, AP
A8: Workforce | B8: mart_workforce_cost_control.csv | C8: src_workforce_cost_control | D8: Connection only | E8: Imported | F8: Payroll, FTE, hiring pressure
A9: SaaS ARR | B9: mart_saas_arr_movement.csv | C9: src_saas_arr_movement | D9: Connection only | E9: Imported | F9: ARR bridge
A10: SaaS Retention | B10: mart_saas_retention.csv | C10: src_saas_retention | D10: Connection only | E10: Imported | F10: GRR, NRR, churn

Sheet 04_Model_Feed_Final
A1: reporting_month_date | B1: billings_gbp | C1: recognised_revenue_actual_gbp | D1: recognised_revenue_total_gbp | E1: cash_collected_gbp | F1: net_unallocated_invoice_exposure_gbp | G1: open_ar_exposure_gbp | H1: revenue_vs_o2c_billings_variance_gbp | I1: revenue_vs_o2c_billings_status | J1: opening_deferred_revenue_gbp | K1: new_billings_deferred_revenue_gbp | L1: recognised_revenue_release_gbp | M1: closing_deferred_revenue_gbp | N1: deferred_revenue_model_variance_gbp | O1: deferred_revenue_model_status | P1: ap_invoice_spend_gbp | Q1: supplier_cash_paid_gbp | R1: open_ap_liability_gbp | S1: overdue_ap_liability_gbp | T1: dpo_proxy_days | U1: ap_control_status | V1: payroll_cost_gbp | W1: base_salary_cost_gbp | X1: employer_tax_cost_gbp | Y1: benefits_cost_gbp | Z1: bonus_accrual_cost_gbp | AA1: active_headcount_count | AB1: active_fte_count | AC1: model_payroll_cost_per_active_fte_gbp | AD1: workforce_control_status | AE1: beginning_arr_gbp | AF1: new_business_arr_gbp | AG1: expansion_arr_gbp | AH1: contraction_arr_gbp | AI1: churn_arr_gbp | AJ1: net_arr_delta_gbp | AK1: arr_monthly_run_rate_source_gbp | AL1: headline_arr_gbp | AM1: saas_arr_control_status | AN1: beginning_active_customer_count | AO1: ending_active_customer_count | AP1: churned_customer_count | AQ1: new_customer_count | AR1: gross_revenue_retention_rate | AS1: net_revenue_retention_rate | AT1: logo_churn_rate | AU1: new_customer_rate | AV1: saas_retention_control_status | AW1: actual_operating_expense_gbp | AX1: actual_operating_profit_gbp | AY1: actual_operating_margin | AZ1: revenue_per_active_fte_gbp | BA1: arr_net_movement_pct | BB1: period_type | BC1: arr_monthly_run_rate_from_active_gbp | BD1: arr_monthly_run_rate_variance_gbp | BE1: arr_bridge_calc_active_arr_gbp | BF1: arr_bridge_variance_gbp | BG1: arr_bridge_status | BH1: arr_monthly_run_rate_status
A2: 44927 | B2: 4257902.4 | C2: 1466626.4 | D2: 1466626.4 | E2: 3771182.3 | F2: 1066716.2 | G2: 1073080.8 | H2: -579996.06 | I2: Definition Difference | J2: -2902.5 | K2: 4257902.4 | L2: 1466626.4 | M2: 2788373.4 | N2: 0 | O2: OK | P2: 291150.19 | Q2: 2972.29 | R2: 0 | S2: 0 | T2: 0 | U2: OK | V2: 4641129.1 | W2: 3456488.9 | X2: 429099.94 | Y2: 343681.92 | Z2: 411858.31 | AA2: 452 | AB2: 452 | AC2: 10267.985 | AD2: Control Exception | AE2: 43815823 | AF2: 1121206 | AG2: 31446.48 | AH2: 7035 | AI2: 19440 | AJ2: 1126278.6 | AK2: 3744791.8 | AL2: 44911762 | AM2: Control Exception | AN2: 2273 | AO2: 2322 | AP2: 1 | AQ2: 55 | AR2: 0.99952588 | AS2: 1.0001135 | AT2: 0.00043994721 | AU2: 0.024197096 | AV2: Control Exception | AW2: 4932279.3 | AX2: -3465652.9 | AY2: -2.36301 | AZ2: 3244.7487 | BA2: 0.025704838 | BB2: Actual | BC2: 3742646.8 | BD2: 2145 | BE2: 44942102 | BF2: -30340 | BG2: Source Definition Difference | BH2: Rounding / Definition Difference
A3: 44958 | B3: 3516657.3 | C3: 1641714.9 | D3: 1641714.9 | E3: 3312454.7 | F3: 565960.16 | G3: 584121.35 | H3: -361757.55 | I3: Minor Variance | J3: 2788373.4 | K3: 3516657.3 | L3: 1641714.9 | M3: 4663315.8 | N3: 0 | O3: OK | P3: 658218.22 | Q3: 144978.52 | R3: 0 | S3: 0 | T3: 0 | U3: OK | V3: 4731102.6 | W3: 3523093.3 | X3: 436666.36 | Y3: 350456.63 | Z3: 420886.39 | AA3: 461 | AB3: 461 | AC3: 10262.696 | AD3: Control Exception | AE3: 44942102 | AF3: 1009401 | AG3: 34172.8 | AH3: 10911 | AI3: 28800 | AJ3: 1003863 | AK3: 3828430.4 | AL3: 45915625 | AM3: Control Exception | AN3: 2328 | AO3: 2377 | AP3: 2 | AQ3: 57 | AR3: 0.99924324 | AS3: 0.99987679 | AT3: 0.00085910653 | AU3: 0.024484536 | AV3: Control Exception | AW3: 5389320.9 | AX3: -3747605.9 | AY3: -2.2827385 | AZ3: 3561.2038 | BA3: 0.022336805 | BB3: Actual | BC3: 3826302.1 | BD3: 2128.3333 | BE3: 45945965 | BF3: -30340 | BG3: Source Definition Difference | BH3: Rounding / Definition Difference
A4: 44986 | B4: 3468525.1 | C4: 1917718.6 | D4: 1917718.6 | E4: 3172057.9 | F4: 730877.7 | G4: 740587.59 | H4: -434410.43 | I4: Definition Difference | J4: 4663315.8 | K4: 3468525.1 | L4: 1917718.6 | M4: 6214122.3 | N4: 0 | O4: OK | P4: 560331.15 | Q4: 806474.41 | R4: 0 | S4: 0 | T4: 0 | U4: OK | V4: 4807431.4 | W4: 3581160.7 | X4: 444946.58 | Y4: 355514.94 | Z4: 425809.18 | AA4: 476 | AB4: 476 | AC4: 10099.646 | AD4: Control Exception | AE4: 45945965 | AF4: 1217219 | AG4: 18291.36 | AH4: 0 | AI4: 24468 | AJ4: 1211241 | AK4: 3929333.8 | AL4: 47126866 | AM4: Control Exception | AN4: 2383 | AO4: 2436 | AP4: 2 | AQ4: 61 | AR4: 0.99959152 | AS4: 0.99986557 | AT4: 0.00083927822 | AU4: 0.025597986 | AV4: Control Exception | AW4: 5367762.6 | AX4: -3450043.9 | AY4: -1.7990355 | AZ4: 4028.8207 | BA4: 0.026362294 | BB4: Actual | BC4: 3927238.8 | BD4: 2095 | BE4: 47157206 | BF4: -30340 | BG4: Source Definition Difference | BH4: Rounding / Definition Difference
A5: 45017 | B5: 3871963.5 | C5: 2122884.7 | D5: 2122884.7 | E5: 3613516.5 | F5: 712640.92 | G5: 720385.8 | H5: -454194.01 | I5: Definition Difference | J5: 6214122.3 | K5: 3871963.5 | L5: 2122884.7 | M5: 7963201 | N5: 0 | O5: OK | P5: 755499.01 | Q5: 446431.7 | R5: 0 | S5: 0 | T5: 0 | U5: OK | V5: 4868707.2 | W5: 3627959.6 | X5: 450272.74 | Y5: 360066.75 | Z5: 430408.16 | AA5: 487 | AB5: 487 | AC5: 9997.3454 | AD5: Control Exception | AE5: 47157206 | AF5: 1002391 | AG5: 6058.32 | AH5: 15302 | AI5: 0 | AJ5: 993248.96 | AK5: 4012087.9 | AL5: 48120115 | AM5: Control Exception | AN5: 2442 | AO5: 2509 | AP5: 0 | AQ5: 73 | AR5: 0.9997964 | AS5: 0.999804 | AT5: 0 | AU5: 0.02989353 | AV5: Control Exception | AW5: 5624206.2 | AX5: -3501321.5 | AY5: -1.6493225 | AZ5: 4359.1062 | BA5: 0.021062507 | BB5: Actual | BC5: 4010009.6 | BD5: 2078.3333 | BE5: 48150455 | BF5: -30340 | BG5: Source Definition Difference | BH5: Rounding / Definition Difference
A6: 45047 | B6: 3491692.5 | C6: 2373771 | D6: 2373771 | E6: 3000694 | F6: 840106.9 | G6: 848665.75 | H6: -349108.41 | I6: Minor Variance | J6: 7963201 | K6: 3491692.5 | L6: 2373771 | M6: 9081122.6 | N6: 0 | O6: OK | P6: 519926.93 | Q6: 642419.77 | R6: 0 | S6: 0 | T6: 0 | U6: OK | V6: 4929130.6 | W6: 3672958.3 | X6: 456789.77 | Y6: 363721.88 | Z6: 435660.61 | AA6: 496 | AB6: 496 | AC6: 9937.7633 | AD6: Control Exception | AE6: 48150455 | AF6: 1529017 | AG6: 21306.72 | AH6: 0 | AI6: 6000 | AJ6: 1544522.9 | AK6: 4140773.1 | AL6: 49664638 | AM6: Control Exception | AN6: 2515 | AO6: 2590 | AP6: 1 | AQ6: 82 | AR6: 0.99999377 | AS6: 1.0003179 | AT6: 0.00039761431 | AU6: 0.032604374 | AV6: Control Exception | AW6: 5449057.5 | AX6: -3075286.5 | AY6: -1.2955279 | AZ6: 4785.8286 | BA6: 0.032077015 | BB6: Actual | BC6: 4138719.8 | BD6: 2053.3333 | BE6: 49694978 | BF6: -30340 | BG6: Source Definition Difference | BH6: Rounding / Definition Difference
A7: 45078 | B7: 4373359.3 | C7: 2624063.5 | D7: 2624063.5 | E7: 3983097.2 | F7: 903803.61 | G7: 917567.49 | H7: -513541.56 | I7: Definition Difference | J7: 9081122.6 | K7: 4373359.3 | L7: 2624063.5 | M7: 10830418 | N7: 0 | O7: OK | P7: 679161.62 | Q7: 500315.7 | R7: 0 | S7: 0 | T7: 0 | U7: OK | V7: 4974433.4 | W7: 3708519.4 | X7: 460709.5 | Y7: 367192.28 | Z7: 438012.17 | AA7: 505 | AB7: 505 | AC7: 9850.3631 | AD7: Control Exception | AE7: 49694978 | AF7: 1192700 | AG7: 60937.08 | AH7: 0 | AI7: 23868 | AJ7: 1230267.7 | AK7: 4243253.8 | AL7: 50894905 | AM7: Control Exception | AN7: 2596 | AO7: 2644 | AP7: 1 | AQ7: 55 | AR7: 0.99963441 | AS7: 1.0007459 | AT7: 0.00038520801 | AU7: 0.021186441 | AV7: Control Exception | AW7: 5653595 | AX7: -3029531.5 | AY7: -1.1545191 | AZ7: 5196.1654 | BA7: 0.024756379 | BB7: Actual | BC7: 4241242.1 | BD7: 2011.6667 | BE7: 50925245 | BF7: -30340 | BG7: Source Definition Difference | BH7: Rounding / Definition Difference
A8: 45108 | B8: 3788027.8 | C8: 2899362.8 | D8: 2899362.8 | E8: 3687227.4 | F8: 550712.28 | G8: 557672.58 | H8: -449911.95 | I8: Definition Difference | J8: 10830418 | K8: 3788027.8 | L8: 2899362.8 | M8: 11719083 | N8: 0 | O8: OK | P8: 588706.85 | Q8: 641704.78 | R8: 0 | S8: 0 | T8: 0 | U8: OK | V8: 5078537 | W8: 3782793.4 | X8: 472093.45 | Y8: 374057.7 | Z8: 449592.45 | AA8: 513 | AB8: 513 | AC8: 9899.6822 | AD8: Control Exception | AE8: 50925245 | AF8: 1062053 | AG8: 41914.44 | AH8: 0 | AI8: 0 | AJ8: 1111895.4 | AK8: 4335895 | AL8: 52006801 | AM8: Control Exception | AN8: 2650 | AO8: 2702 | AP8: 0 | AQ8: 57 | AR8: 1.0001119 | AS8: 1.0009787 | AT8: 0 | AU8: 0.021509434 | AV8: Control Exception | AW8: 5667243.8 | AX8: -2767881 | AY8: -0.95465151 | AZ8: 5651.7793 | BA8: 0.021833873 | BB8: Actual | BC8: 4333900.1 | BD8: 1995 | BE8: 52037141 | BF8: -30340 | BG8: Source Definition Difference | BH8: Rounding / Definition Difference
A9: 45139 | B9: 4187386.9 | C9: 3163202.6 | D9: 3163202.6 | E9: 4042353.8 | F9: 631174.55 | G9: 648072.02 | H9: -486141.47 | I9: Definition Difference | J9: 11719083 | K9: 4187386.9 | L9: 3163202.6 | M9: 12743268 | N9: 0 | O9: OK | P9: 863983.56 | Q9: 635031.87 | R9: 0 | S9: 0 | T9: 0 | U9: OK | V9: 5101870.2 | W9: 3800470.1 | X9: 473456.06 | Y9: 375661.95 | Z9: 452282.06 | AA9: 520 | AB9: 520 | AC9: 9811.2888 | AD9: Control Exception | AE9: 52037141 | AF9: 1428249 | AG9: 13973.16 | AH9: 10209 | AI9: 65430 | AJ9: 1366683.8 | AK9: 4449752 | AL9: 53373484 | AM9: Control Exception | AN9: 2708 | AO9: 2769 | AP9: 2 | AQ9: 69 | AR9: 0.998656 | AS9: 0.99881498 | AT9: 0.00073855244 | AU9: 0.025480059 | AV9: Control Exception | AW9: 5965853.7 | AX9: -2802651.1 | AY9: -0.88601695 | AZ9: 6083.0819 | BA9: 0.026263621 | BB9: Actual | BC9: 4447790.4 | BD9: 1961.6667 | BE9: 53403824 | BF9: -30340 | BG9: Source Definition Difference | BH9: Rounding / Definition Difference
A10: 45170 | B10: 4154014.5 | C10: 3373435.1 | D10: 3373435.1 | E10: 3796047.9 | F10: 813438.32 | G10: 822694.7 | H10: -455471.75 | I10: Minor Variance | J10: 12743268 | K10: 4154014.5 | L10: 3373435.1 | M10: 13523847 | N10: 0 | O10: OK | P10: 360866.05 | Q10: 619227.97 | R10: 0 | S10: 0 | T10: 0 | U10: OK | V10: 5180494.3 | W10: 3861616.9 | X10: 479682.79 | Y10: 381778.74 | Z10: 457415.93 | AA10: 531 | AB10: 531 | AC10: 9756.1098 | AD10: Control Exception | AE10: 53403824 | AF10: 828130 | AG10: 59171.52 | AH10: 22442 | AI10: 0 | AJ10: 865058.48 | AK10: 4521823.6 | AL10: 54238543 | AM10: Control Exception | AN10: 2775 | AO10: 2831 | AP10: 0 | AQ10: 62 | AR10: 0.99968651 | AS10: 1.0006878 | AT10: 0 | AU10: 0.022342342 | AV10: Control Exception | AW10: 5541360.4 | AX10: -2167925.3 | AY10: -0.6426462 | AZ10: 6352.9851 | BA10: 0.016198437 | BB10: Actual | BC10: 4519878.6 | BD10: 1945 | BE10: 54268883 | BF10: -30340 | BG10: Source Definition Difference | BH10: Rounding / Definition Difference
A11: 45200 | B11: 4065230 | C11: 3639853 | D11: 3639853 | E11: 3921672.6 | F11: 632971.96 | G11: 644302.72 | H11: -489414.58 | I11: Definition Difference | J11: 13523847 | K11: 4065230 | L11: 3639853 | M11: 13949224 | N11: 0 | O11: OK | P11: 593476.8 | Q11: 397281.74 | R11: 0 | S11: 0 | T11: 0 | U11: OK | V11: 5252380.2 | W11: 3916179.1 | X11: 485548.37 | Y11: 387643.59 | Z11: 463009.14 | AA11: 536 | AB11: 536 | AC11: 9799.2168 | AD11: Control Exception | AE11: 54268883 | AF11: 1028968 | AG11: 44596.08 | AH11: 5224 | AI11: 39600 | AJ11: 1028740.6 | AK11: 4607543.6 | AL11: 55280483 | AM11: Control Exception | AN11: 2837 | AO11: 2886 | AP11: 3 | AQ11: 58 | AR11: 0.99954441 | AS11: 0.9999958 | AT11: 0.0010574551 | AU11: 0.020444131 | AV11: Control Exception | AW11: 5845857 | AX11: -2206003.9 | AY11: -0.60606951 | AZ11: 6790.7706 | BA11: 0.018956362 | BB11: Actual | BC11: 4606707 | BD11: 836.66667 | BE11: 55297623 | BF11: -17140 | BG11: Source Definition Difference | BH11: Rounding / Definition Difference
A12: 45231 | B12: 3442796.8 | C12: 3770045.8 | D12: 3770045.8 | E12: 3229596.3 | F12: 613074.49 | G12: 620715.9 | H12: -399873.94 | I12: Definition Difference | J12: 13949224 | K12: 3442796.8 | L12: 3770045.8 | M12: 13626975 | N12: 5000 | O12: Check | P12: 592750.93 | Q12: 544597.98 | R12: 0 | S12: 0 | T12: 0 | U12: OK | V12: 5366818.2 | W12: 4001316.7 | X12: 496390.03 | Y12: 396466.42 | Z12: 472645.06 | AA12: 546 | AB12: 546 | AC12: 9829.3375 | AD12: Control Exception | AE12: 55297623 | AF12: 861511 | AG12: 42329.88 | AH12: 9923 | AI12: 14100 | AJ12: 879817 | AK12: 4680853.4 | AL12: 56160300 | AM12: Control Exception | AN12: 2893 | AO12: 2936 | AP12: 2 | AQ12: 52 | AR12: 0.99992906 | AS12: 1.0003311 | AT12: 0.00069132389 | AU12: 0.017974421 | AV12: Control Exception | AW12: 5959569.2 | AX12: -2189523.4 | AY12: -0.58076839 | AZ12: 6904.8458 | BA12: 0.015910575 | BB12: Actual | BC12: 4680025 | BD12: 828.33333 | BE12: 56177440 | BF12: -17140 | BG12: Source Definition Difference | BH12: Rounding / Definition Difference
A13: 45261 | B13: 4361648.7 | C13: 4105386.4 | D13: 4105386.4 | E13: 3925204.4 | F13: 918439 | G13: 933546.37 | H13: -481994.66 | I13: Minor Variance | J13: 13621975 | K13: 4361648.7 | L13: 4105386.4 | M13: 13878237 | N13: 0 | O13: OK | P13: 469030.83 | Q13: 654590.81 | R13: 0 | S13: 0 | T13: 0 | U13: OK | V13: 5390038.8 | W13: 4018454.5 | X13: 499717.76 | Y13: 398057.85 | Z13: 473808.73 | AA13: 552 | AB13: 552 | AC13: 9764.563 | AD13: Control Exception | AE13: 56177440 | AF13: 1442518 | AG13: 72285.48 | AH13: 48552 | AI13: 50760 | AJ13: 1415492 | AK13: 4798802.7 | AL13: 57572912 | AM13: Control Exception | AN13: 2943 | AO13: 2995 | AP13: 5 | AQ13: 64 | AR13: 0.99858997 | AS13: 0.99951891 | AT13: 0.0016989467 | AU13: 0.021746517 | AV13: Control Exception | AW13: 5859069.6 | AX13: -1753683.2 | AY13: -0.42716643 | AZ13: 7437.2942 | BA13: 0.025196804 | BB13: Actual | BC13: 4797742.7 | BD13: 1060 | BE13: 57592932 | BF13: -20020 | BG13: Source Definition Difference | BH13: Rounding / Definition Difference
... A43: 46174 | B43: 6028900.7 | C43: 5797387.9 | D43: 5797387.9 | E43: 339676.06 | F43: 6393155.4 | G43: 6393361 | H43: -703930.73 | I43: Definition Difference | J43: 21266996 | K43: 6028900.7 | L43: 5797387.9 | M43: 21498509 | N43: 0 | O43: OK | P43: 77774.25 | Q43: 75311.75 | R43: 2647064 | S43: 2068723.2 | T43: 134.23667 | U43: OK | V43: 7655791.2 | W43: 5714669.1 | X43: 711755.81 | Y43: 558714.83 | Z43: 670651.46 | AA43: 854 | AB43: 854 | AC43: 8964.6267 | AD43: Control Exception | AE43: 69290095 | AF43: 0 | AG43: 1304.76 | AH43: 0 | AI43: 6000 | AJ43: -1747089 | AK43: 5627492.2 | AL43: 67446138 | AM43: Control Exception | AN43: 3632 | AO43: 3518 | AP43: 1 | AQ43: 0 | AR43: 0.97534477 | AS43: 0.97478588 | AT43: 0.0002753304 | AU43: 0 | AV43: Control Exception | AW43: 7733565.4 | AX43: -1936177.6 | AY43: -0.33397413 | AZ43: 6788.5104 | BA43: -0.025214124 | BB43: Actual | BC43: 5620511.5 | BD43: 6980.6367 | BE43: 67543006 | BF43: -96867.64 | BG43: Source Definition Difference | BH43: Rounding / Definition Difference

Sheet 05_Monthly_Model
A1: Nexus Technologies — Monthly Financial Model
A2: Currency: GBP / Units: £ actual
A4: Month | B4: ='02_Control'!$B$8 -> 44927 | C4: =EDATE(B4,1) -> 44958 | D4: =EDATE(C4,1) -> 44986 | E4: =EDATE(D4,1) -> 45017 | F4: =EDATE(E4,1) -> 45047 | G4: =EDATE(F4,1) -> 45078 | H4: =EDATE(G4,1) -> 45108 | I4: =EDATE(H4,1) -> 45139 | J4: =EDATE(I4,1) -> 45170 | ... CG4: =EDATE(CF4,1) -> 47453
A5: Period Type | B5: =IF(B4<='02_Control'!$B$9,"Actual","Forecast") -> Actual | C5: =IF(C4<='02_Control'!$B$9,"Actual","Forecast") -> Actual | D5: =IF(D4<='02_Control'!$B$9,"Actual","Forecast") -> Actual | E5: =IF(E4<='02_Control'!$B$9,"Actual","Forecast") -> Actual | F5: =IF(F4<='02_Control'!$B$9,"Actual","Forecast") -> Actual | G5: =IF(G4<='02_Control'!$B$9,"Actual","Forecast") -> Actual | H5: =IF(H4<='02_Control'!$B$9,"Actual","Forecast") -> Actual | I5: =IF(I4<='02_Control'!$B$9,"Actual","Forecast") -> Actual | ... CG5: =IF(CG4<='02_Control'!$B$9,"Actual","Forecast") -> Forecast
A6: Calendar Year | B6: =YEAR(B4) -> 2023 | C6: =YEAR(C4) -> 2023 | D6: =YEAR(D4) -> 2023 | E6: =YEAR(E4) -> 2023 | F6: =YEAR(F4) -> 2023 | G6: =YEAR(G4) -> 2023 | H6: =YEAR(H4) -> 2023 | I6: =YEAR(I4) -> 2023 | ... CG6: =YEAR(CG4) -> 2029
A7: Quarter | B7: ="Q"&ROUNDUP(MONTH(B4)/3,0) -> Q1 | C7: ="Q"&ROUNDUP(MONTH(C4)/3,0) -> Q1 | D7: ="Q"&ROUNDUP(MONTH(D4)/3,0) -> Q1 | E7: ="Q"&ROUNDUP(MONTH(E4)/3,0) -> Q2 | F7: ="Q"&ROUNDUP(MONTH(F4)/3,0) -> Q2 | G7: ="Q"&ROUNDUP(MONTH(G4)/3,0) -> Q2 | H7: ="Q"&ROUNDUP(MONTH(H4)/3,0) -> Q3 | I7: ="Q"&ROUNDUP(MONTH(I4)/3,0) -> Q3 | ... CG7: ="Q"&ROUNDUP(MONTH(CG4)/3,0) -> Q4
A9: Revenue & ARR
A10: Recognised Revenue | B10: =IF(B$5="Actual",SUMIFS(tbl_model_feed_final[recognised_revenue_actual_gbp],tbl_model_feed_final[reporting_month_date],B$4)/'02_Control'!$B$18,"") -> 1466626.4 | C10: =IF(C$5="Actual",SUMIFS(tbl_model_feed_final[recognised_revenue_actual_gbp],tbl_model_feed_final[reporting_month_date],C$4)/'02_Control'!$B$18,"") -> 1641714.9 | D10: =IF(D$5="Actual",SUMIFS(tbl_model_feed_final[recognised_revenue_actual_gbp],tbl_model_feed_final[reporting_month_date],D$4)/'02_Control'!$B$18,"") -> 1917718.6 | E10: =IF(E$5="Actual",SUMIFS(tbl_model_feed_final[recognised_revenue_actual_gbp],tbl_model_feed_final[reporting_month_date],E$4)/'02_Control'!$B$18,"") -> 2122884.7 | F10: =IF(F$5="Actual",SUMIFS(tbl_model_feed_final[recognised_revenue_actual_gbp],tbl_model_feed_final[reporting_month_date],F$4)/'02_Control'!$B$18,"") -> 2373771 | G10: =IF(G$5="Actual",SUMIFS(tbl_model_feed_final[recognised_revenue_actual_gbp],tbl_model_feed_final[reporting_month_date],G$4)/'02_Control'!$B$18,"") -> 2624063.5 | H10: =IF(H$5="Actual",SUMIFS(tbl_model_feed_final[recognised_revenue_actual_gbp],tbl_model_feed_final[reporting_month_date],H$4)/'02_Control'!$B$18,"") -> 2899362.8 | I10: =IF(I$5="Actual",SUMIFS(tbl_model_feed_final[recognised_revenue_actual_gbp],tbl_model_feed_final[reporting_month_date],I$4)/'02_Control'!$B$18,"") -> 3163202.6 | ... AQ10: =IF(AQ$5="Actual",SUMIFS(tbl_model_feed_final[recognised_revenue_actual_gbp],tbl_model_feed_final[reporting_month_date],AQ$4)/'02_Control'!$B$18,"") -> 5797387.9 | AR10: =IF(AR$5="Actual",SUMIFS(tbl_model_feed_final[recognised_revenue_actual_gbp],tbl_model_feed_final[reporting_month_date],AR$4)/'02_Control'!$B$18,AQ10*(1+_xlfn.XLOOKUP("Recognised Revenue Growth %",tbl_assumptions[Driver],tbl_assumptions[Selected Scenario]))) -> 5855361.7 | AS10: =IF(AS$5="Actual",SUMIFS(tbl_model_feed_final[recognised_revenue_actual_gbp],tbl_model_feed_final[reporting_month_date],AS$4)/'02_Control'!$B$18,AR10*(1+_xlfn.XLOOKUP("Recognised Revenue Growth %",tbl_assumptions[Driver],tbl_assumptions[Selected Scenario]))) -> 5913915.4 | AT10: =IF(AT$5="Actual",SUMIFS(tbl_model_feed_final[recognised_revenue_actual_gbp],tbl_model_feed_final[reporting_month_date],AT$4)/'02_Control'!$B$18,AS10*(1+_xlfn.XLOOKUP("Recognised Revenue Growth %",tbl_assumptions[Driver],tbl_assumptions[Selected Scenario]))) -> 5973054.5 | AU10: =IF(AU$5="Actual",SUMIFS(tbl_model_feed_final[recognised_revenue_actual_gbp],tbl_model_feed_final[reporting_month_date],AU$4)/'02_Control'!$B$18,AT10*(1+_xlfn.XLOOKUP("Recognised Revenue Growth %",tbl_assumptions[Driver],tbl_assumptions[Selected Scenario]))) -> 6032785.1 | AV10: =IF(AV$5="Actual",SUMIFS(tbl_model_feed_final[recognised_revenue_actual_gbp],tbl_model_feed_final[reporting_month_date],AV$4)/'02_Control'!$B$18,AU10*(1+_xlfn.XLOOKUP("Recognised Revenue Growth %",tbl_assumptions[Driver],tbl_assumptions[Selected Scenario]))) -> 6093112.9 | AW10: =IF(AW$5="Actual",SUMIFS(tbl_model_feed_final[recognised_revenue_actual_gbp],tbl_model_feed_final[reporting_month_date],AW$4)/'02_Control'!$B$18,AV10*(1+_xlfn.XLOOKUP("Recognised Revenue Growth %",tbl_assumptions[Driver],tbl_assumptions[Selected Scenario]))) -> 6154044 | AX10: =IF(AX$5="Actual",SUMIFS(tbl_model_feed_final[recognised_revenue_actual_gbp],tbl_model_feed_final[reporting_month_date],AX$4)/'02_Control'!$B$18,AW10*(1+_xlfn.XLOOKUP("Recognised Revenue Growth %",tbl_assumptions[Driver],tbl_assumptions[Selected Scenario]))) -> 6215584.5 | AY10: =IF(AY$5="Actual",SUMIFS(tbl_model_feed_final[recognised_revenue_actual_gbp],tbl_model_feed_final[reporting_month_date],AY$4)/'02_Control'!$B$18,AX10*(1+_xlfn.XLOOKUP("Recognised Revenue Growth %",tbl_assumptions[Driver],tbl_assumptions[Selected Scenario]))) -> 6277740.3 | ... CG10: =IF(CG$5="Actual",SUMIFS(tbl_model_feed_final[recognised_revenue_actual_gbp],tbl_model_feed_final[reporting_month_date],CG$4)/'02_Control'!$B$18,CF10*(1+_xlfn.XLOOKUP("Recognised Revenue Growth %",tbl_assumptions[Driver],tbl_assumptions[Selected Scenario]))) -> 8805014.1
A11: Billings | B11: =IF(B$5="Actual",SUMIFS(tbl_model_feed_final[billings_gbp],tbl_model_feed_final[reporting_month_date],B$4)/'02_Control'!$B$18,"") -> 4257902.4 | C11: =IF(C$5="Actual",SUMIFS(tbl_model_feed_final[billings_gbp],tbl_model_feed_final[reporting_month_date],C$4)/'02_Control'!$B$18,"") -> 3516657.3 | D11: =IF(D$5="Actual",SUMIFS(tbl_model_feed_final[billings_gbp],tbl_model_feed_final[reporting_month_date],D$4)/'02_Control'!$B$18,"") -> 3468525.1 | E11: =IF(E$5="Actual",SUMIFS(tbl_model_feed_final[billings_gbp],tbl_model_feed_final[reporting_month_date],E$4)/'02_Control'!$B$18,"") -> 3871963.5 | F11: =IF(F$5="Actual",SUMIFS(tbl_model_feed_final[billings_gbp],tbl_model_feed_final[reporting_month_date],F$4)/'02_Control'!$B$18,"") -> 3491692.5 | G11: =IF(G$5="Actual",SUMIFS(tbl_model_feed_final[billings_gbp],tbl_model_feed_final[reporting_month_date],G$4)/'02_Control'!$B$18,"") -> 4373359.3 | H11: =IF(H$5="Actual",SUMIFS(tbl_model_feed_final[billings_gbp],tbl_model_feed_final[reporting_month_date],H$4)/'02_Control'!$B$18,"") -> 3788027.8 | I11: =IF(I$5="Actual",SUMIFS(tbl_model_feed_final[billings_gbp],tbl_model_feed_final[reporting_month_date],I$4)/'02_Control'!$B$18,"") -> 4187386.9 | ... AQ11: =IF(AQ$5="Actual",SUMIFS(tbl_model_feed_final[billings_gbp],tbl_model_feed_final[reporting_month_date],AQ$4)/'02_Control'!$B$18,"") -> 6028900.7 | AR11: =IF(AR$5="Actual",SUMIFS(tbl_model_feed_final[billings_gbp],tbl_model_feed_final[reporting_month_date],AR$4)/'02_Control'!$B$18,AQ11*(1+_xlfn.XLOOKUP("Billings Growth %",tbl_assumptions[Driver],tbl_assumptions[Selected Scenario]))) -> 6077131.9 | AS11: =IF(AS$5="Actual",SUMIFS(tbl_model_feed_final[billings_gbp],tbl_model_feed_final[reporting_month_date],AS$4)/'02_Control'!$B$18,AR11*(1+_xlfn.XLOOKUP("Billings Growth %",tbl_assumptions[Driver],tbl_assumptions[Selected Scenario]))) -> 6125749 | AT11: =IF(AT$5="Actual",SUMIFS(tbl_model_feed_final[billings_gbp],tbl_model_feed_final[reporting_month_date],AT$4)/'02_Control'!$B$18,AS11*(1+_xlfn.XLOOKUP("Billings Growth %",tbl_assumptions[Driver],tbl_assumptions[Selected Scenario]))) -> 6174755 | AU11: =IF(AU$5="Actual",SUMIFS(tbl_model_feed_final[billings_gbp],tbl_model_feed_final[reporting_month_date],AU$4)/'02_Control'!$B$18,AT11*(1+_xlfn.XLOOKUP("Billings Growth %",tbl_assumptions[Driver],tbl_assumptions[Selected Scenario]))) -> 6224153 | AV11: =IF(AV$5="Actual",SUMIFS(tbl_model_feed_final[billings_gbp],tbl_model_feed_final[reporting_month_date],AV$4)/'02_Control'!$B$18,AU11*(1+_xlfn.XLOOKUP("Billings Growth %",tbl_assumptions[Driver],tbl_assumptions[Selected Scenario]))) -> 6273946.2 | AW11: =IF(AW$5="Actual",SUMIFS(tbl_model_feed_final[billings_gbp],tbl_model_feed_final[reporting_month_date],AW$4)/'02_Control'!$B$18,AV11*(1+_xlfn.XLOOKUP("Billings Growth %",tbl_assumptions[Driver],tbl_assumptions[Selected Scenario]))) -> 6324137.8 | AX11: =IF(AX$5="Actual",SUMIFS(tbl_model_feed_final[billings_gbp],tbl_model_feed_final[reporting_month_date],AX$4)/'02_Control'!$B$18,AW11*(1+_xlfn.XLOOKUP("Billings Growth %",tbl_assumptions[Driver],tbl_assumptions[Selected Scenario]))) -> 6374730.9 | AY11: =IF(AY$5="Actual",SUMIFS(tbl_model_feed_final[billings_gbp],tbl_model_feed_final[reporting_month_date],AY$4)/'02_Control'!$B$18,AX11*(1+_xlfn.XLOOKUP("Billings Growth %",tbl_assumptions[Driver],tbl_assumptions[Selected Scenario]))) -> 6425728.8 | ... CG11: =IF(CG$5="Actual",SUMIFS(tbl_model_feed_final[billings_gbp],tbl_model_feed_final[reporting_month_date],CG$4)/'02_Control'!$B$18,CF11*(1+_xlfn.XLOOKUP("Billings Growth %",tbl_assumptions[Driver],tbl_assumptions[Selected Scenario]))) -> 8425205.1
A12: Headline ARR | B12: =IF(B$5="Actual",SUMIFS(tbl_model_feed_final[headline_arr_gbp],tbl_model_feed_final[reporting_month_date],B$4)/'02_Control'!$B$18,"") -> 44911762 | C12: =IF(C$5="Actual",SUMIFS(tbl_model_feed_final[headline_arr_gbp],tbl_model_feed_final[reporting_month_date],C$4)/'02_Control'!$B$18,"") -> 45915625 | D12: =IF(D$5="Actual",SUMIFS(tbl_model_feed_final[headline_arr_gbp],tbl_model_feed_final[reporting_month_date],D$4)/'02_Control'!$B$18,"") -> 47126866 | E12: =IF(E$5="Actual",SUMIFS(tbl_model_feed_final[headline_arr_gbp],tbl_model_feed_final[reporting_month_date],E$4)/'02_Control'!$B$18,"") -> 48120115 | F12: =IF(F$5="Actual",SUMIFS(tbl_model_feed_final[headline_arr_gbp],tbl_model_feed_final[reporting_month_date],F$4)/'02_Control'!$B$18,"") -> 49664638 | G12: =IF(G$5="Actual",SUMIFS(tbl_model_feed_final[headline_arr_gbp],tbl_model_feed_final[reporting_month_date],G$4)/'02_Control'!$B$18,"") -> 50894905 | H12: =IF(H$5="Actual",SUMIFS(tbl_model_feed_final[headline_arr_gbp],tbl_model_feed_final[reporting_month_date],H$4)/'02_Control'!$B$18,"") -> 52006801 | I12: =IF(I$5="Actual",SUMIFS(tbl_model_feed_final[headline_arr_gbp],tbl_model_feed_final[reporting_month_date],I$4)/'02_Control'!$B$18,"") -> 53373484 | ... AQ12: =IF(AQ$5="Actual",SUMIFS(tbl_model_feed_final[headline_arr_gbp],tbl_model_feed_final[reporting_month_date],AQ$4)/'02_Control'!$B$18,"") -> 67446138 | AR12: =IF(AR$5="Actual",SUMIFS(tbl_model_feed_final[headline_arr_gbp],tbl_model_feed_final[reporting_month_date],AR$4)/'02_Control'!$B$18,AQ12*(1+_xlfn.XLOOKUP("Headline ARR Growth %",tbl_assumptions[Driver],tbl_assumptions[Selected Scenario]))) -> 68053154 | AS12: =IF(AS$5="Actual",SUMIFS(tbl_model_feed_final[headline_arr_gbp],tbl_model_feed_final[reporting_month_date],AS$4)/'02_Control'!$B$18,AR12*(1+_xlfn.XLOOKUP("Headline ARR Growth %",tbl_assumptions[Driver],tbl_assumptions[Selected Scenario]))) -> 68665632 | AT12: =IF(AT$5="Actual",SUMIFS(tbl_model_feed_final[headline_arr_gbp],tbl_model_feed_final[reporting_month_date],AT$4)/'02_Control'!$B$18,AS12*(1+_xlfn.XLOOKUP("Headline ARR Growth %",tbl_assumptions[Driver],tbl_assumptions[Selected Scenario]))) -> 69283623 | AU12: =IF(AU$5="Actual",SUMIFS(tbl_model_feed_final[headline_arr_gbp],tbl_model_feed_final[reporting_month_date],AU$4)/'02_Control'!$B$18,AT12*(1+_xlfn.XLOOKUP("Headline ARR Growth %",tbl_assumptions[Driver],tbl_assumptions[Selected Scenario]))) -> 69907175 | AV12: =IF(AV$5="Actual",SUMIFS(tbl_model_feed_final[headline_arr_gbp],tbl_model_feed_final[reporting_month_date],AV$4)/'02_Control'!$B$18,AU12*(1+_xlfn.XLOOKUP("Headline ARR Growth %",tbl_assumptions[Driver],tbl_assumptions[Selected Scenario]))) -> 70536340 | AW12: =IF(AW$5="Actual",SUMIFS(tbl_model_feed_final[headline_arr_gbp],tbl_model_feed_final[reporting_month_date],AW$4)/'02_Control'!$B$18,AV12*(1+_xlfn.XLOOKUP("Headline ARR Growth %",tbl_assumptions[Driver],tbl_assumptions[Selected Scenario]))) -> 71171167 | AX12: =IF(AX$5="Actual",SUMIFS(tbl_model_feed_final[headline_arr_gbp],tbl_model_feed_final[reporting_month_date],AX$4)/'02_Control'!$B$18,AW12*(1+_xlfn.XLOOKUP("Headline ARR Growth %",tbl_assumptions[Driver],tbl_assumptions[Selected Scenario]))) -> 71811707 | AY12: =IF(AY$5="Actual",SUMIFS(tbl_model_feed_final[headline_arr_gbp],tbl_model_feed_final[reporting_month_date],AY$4)/'02_Control'!$B$18,AX12*(1+_xlfn.XLOOKUP("Headline ARR Growth %",tbl_assumptions[Driver],tbl_assumptions[Selected Scenario]))) -> 72458013 | ... CG12: =IF(CG$5="Actual",SUMIFS(tbl_model_feed_final[headline_arr_gbp],tbl_model_feed_final[reporting_month_date],CG$4)/'02_Control'!$B$18,CF12*(1+_xlfn.XLOOKUP("Headline ARR Growth %",tbl_assumptions[Driver],tbl_assumptions[Selected Scenario]))) -> 98262107
A13: Net ARR Movement | B13: =IF(B$5="Actual",SUMIFS(tbl_model_feed_final[net_arr_delta_gbp],tbl_model_feed_final[reporting_month_date],B$4)/'02_Control'!$B$18,"") -> 1126278.6 | C13: =IF(C$5="Actual",SUMIFS(tbl_model_feed_final[net_arr_delta_gbp],tbl_model_feed_final[reporting_month_date],C$4)/'02_Control'!$B$18,"") -> 1003863 | D13: =IF(D$5="Actual",SUMIFS(tbl_model_feed_final[net_arr_delta_gbp],tbl_model_feed_final[reporting_month_date],D$4)/'02_Control'!$B$18,"") -> 1211241 | E13: =IF(E$5="Actual",SUMIFS(tbl_model_feed_final[net_arr_delta_gbp],tbl_model_feed_final[reporting_month_date],E$4)/'02_Control'!$B$18,"") -> 993248.96 | F13: =IF(F$5="Actual",SUMIFS(tbl_model_feed_final[net_arr_delta_gbp],tbl_model_feed_final[reporting_month_date],F$4)/'02_Control'!$B$18,"") -> 1544522.9 | G13: =IF(G$5="Actual",SUMIFS(tbl_model_feed_final[net_arr_delta_gbp],tbl_model_feed_final[reporting_month_date],G$4)/'02_Control'!$B$18,"") -> 1230267.7 | H13: =IF(H$5="Actual",SUMIFS(tbl_model_feed_final[net_arr_delta_gbp],tbl_model_feed_final[reporting_month_date],H$4)/'02_Control'!$B$18,"") -> 1111895.4 | I13: =IF(I$5="Actual",SUMIFS(tbl_model_feed_final[net_arr_delta_gbp],tbl_model_feed_final[reporting_month_date],I$4)/'02_Control'!$B$18,"") -> 1366683.8 | ... AQ13: =IF(AQ$5="Actual",SUMIFS(tbl_model_feed_final[net_arr_delta_gbp],tbl_model_feed_final[reporting_month_date],AQ$4)/'02_Control'!$B$18,"") -> -1747089 | AR13: =IF(AR$5="Actual",SUMIFS(tbl_model_feed_final[net_arr_delta_gbp],tbl_model_feed_final[reporting_month_date],AR$4)/'02_Control'!$B$18,AR12-AQ12) -> 607015.25 | AS13: =IF(AS$5="Actual",SUMIFS(tbl_model_feed_final[net_arr_delta_gbp],tbl_model_feed_final[reporting_month_date],AS$4)/'02_Control'!$B$18,AS12-AR12) -> 612478.38 | AT13: =IF(AT$5="Actual",SUMIFS(tbl_model_feed_final[net_arr_delta_gbp],tbl_model_feed_final[reporting_month_date],AT$4)/'02_Control'!$B$18,AT12-AS12) -> 617990.69 | AU13: =IF(AU$5="Actual",SUMIFS(tbl_model_feed_final[net_arr_delta_gbp],tbl_model_feed_final[reporting_month_date],AU$4)/'02_Control'!$B$18,AU12-AT12) -> 623552.6 | AV13: =IF(AV$5="Actual",SUMIFS(tbl_model_feed_final[net_arr_delta_gbp],tbl_model_feed_final[reporting_month_date],AV$4)/'02_Control'!$B$18,AV12-AU12) -> 629164.58 | AW13: =IF(AW$5="Actual",SUMIFS(tbl_model_feed_final[net_arr_delta_gbp],tbl_model_feed_final[reporting_month_date],AW$4)/'02_Control'!$B$18,AW12-AV12) -> 634827.06 | AX13: =IF(AX$5="Actual",SUMIFS(tbl_model_feed_final[net_arr_delta_gbp],tbl_model_feed_final[reporting_month_date],AX$4)/'02_Control'!$B$18,AX12-AW12) -> 640540.5 | AY13: =IF(AY$5="Actual",SUMIFS(tbl_model_feed_final[net_arr_delta_gbp],tbl_model_feed_final[reporting_month_date],AY$4)/'02_Control'!$B$18,AY12-AX12) -> 646305.37 | ... CG13: =IF(CG$5="Actual",SUMIFS(tbl_model_feed_final[net_arr_delta_gbp],tbl_model_feed_final[reporting_month_date],CG$4)/'02_Control'!$B$18,CG12-CF12) -> 876470.72
A14: GRR | B14: =IF(B$5="Actual",SUMIFS(tbl_model_feed_final[gross_revenue_retention_rate],tbl_model_feed_final[reporting_month_date],B$4),"") -> 0.99952588 | C14: =IF(C$5="Actual",SUMIFS(tbl_model_feed_final[gross_revenue_retention_rate],tbl_model_feed_final[reporting_month_date],C$4),"") -> 0.99924324 | D14: =IF(D$5="Actual",SUMIFS(tbl_model_feed_final[gross_revenue_retention_rate],tbl_model_feed_final[reporting_month_date],D$4),"") -> 0.99959152 | E14: =IF(E$5="Actual",SUMIFS(tbl_model_feed_final[gross_revenue_retention_rate],tbl_model_feed_final[reporting_month_date],E$4),"") -> 0.9997964 | F14: =IF(F$5="Actual",SUMIFS(tbl_model_feed_final[gross_revenue_retention_rate],tbl_model_feed_final[reporting_month_date],F$4),"") -> 0.99999377 | G14: =IF(G$5="Actual",SUMIFS(tbl_model_feed_final[gross_revenue_retention_rate],tbl_model_feed_final[reporting_month_date],G$4),"") -> 0.99963441 | H14: =IF(H$5="Actual",SUMIFS(tbl_model_feed_final[gross_revenue_retention_rate],tbl_model_feed_final[reporting_month_date],H$4),"") -> 1.0001119 | I14: =IF(I$5="Actual",SUMIFS(tbl_model_feed_final[gross_revenue_retention_rate],tbl_model_feed_final[reporting_month_date],I$4),"") -> 0.998656 | ... AQ14: =IF(AQ$5="Actual",SUMIFS(tbl_model_feed_final[gross_revenue_retention_rate],tbl_model_feed_final[reporting_month_date],AQ$4),"") -> 0.97534477 | AR14: =IF(AR$5="Actual",SUMIFS(tbl_model_feed_final[gross_revenue_retention_rate],tbl_model_feed_final[reporting_month_date],AR$4),_xlfn.XLOOKUP("GRR",tbl_assumptions[Driver],tbl_assumptions[Selected Scenario])) -> 0.91 | AS14: =IF(AS$5="Actual",SUMIFS(tbl_model_feed_final[gross_revenue_retention_rate],tbl_model_feed_final[reporting_month_date],AS$4),_xlfn.XLOOKUP("GRR",tbl_assumptions[Driver],tbl_assumptions[Selected Scenario])) -> 0.91 | AT14: =IF(AT$5="Actual",SUMIFS(tbl_model_feed_final[gross_revenue_retention_rate],tbl_model_feed_final[reporting_month_date],AT$4),_xlfn.XLOOKUP("GRR",tbl_assumptions[Driver],tbl_assumptions[Selected Scenario])) -> 0.91 | AU14: =IF(AU$5="Actual",SUMIFS(tbl_model_feed_final[gross_revenue_retention_rate],tbl_model_feed_final[reporting_month_date],AU$4),_xlfn.XLOOKUP("GRR",tbl_assumptions[Driver],tbl_assumptions[Selected Scenario])) -> 0.91 | AV14: =IF(AV$5="Actual",SUMIFS(tbl_model_feed_final[gross_revenue_retention_rate],tbl_model_feed_final[reporting_month_date],AV$4),_xlfn.XLOOKUP("GRR",tbl_assumptions[Driver],tbl_assumptions[Selected Scenario])) -> 0.91 | AW14: =IF(AW$5="Actual",SUMIFS(tbl_model_feed_final[gross_revenue_retention_rate],tbl_model_feed_final[reporting_month_date],AW$4),_xlfn.XLOOKUP("GRR",tbl_assumptions[Driver],tbl_assumptions[Selected Scenario])) -> 0.91 | AX14: =IF(AX$5="Actual",SUMIFS(tbl_model_feed_final[gross_revenue_retention_rate],tbl_model_feed_final[reporting_month_date],AX$4),_xlfn.XLOOKUP("GRR",tbl_assumptions[Driver],tbl_assumptions[Selected Scenario])) -> 0.91 | AY14: =IF(AY$5="Actual",SUMIFS(tbl_model_feed_final[gross_revenue_retention_rate],tbl_model_feed_final[reporting_month_date],AY$4),_xlfn.XLOOKUP("GRR",tbl_assumptions[Driver],tbl_assumptions[Selected Scenario])) -> 0.91 | ... CG14: =IF(CG$5="Actual",SUMIFS(tbl_model_feed_final[gross_revenue_retention_rate],tbl_model_feed_final[reporting_month_date],CG$4),_xlfn.XLOOKUP("GRR",tbl_assumptions[Driver],tbl_assumptions[Selected Scenario])) -> 0.91
A15: NRR | B15: =IF(B$5="Actual",SUMIFS(tbl_model_feed_final[net_revenue_retention_rate],tbl_model_feed_final[reporting_month_date],B$4),"") -> 1.0001135 | C15: =IF(C$5="Actual",SUMIFS(tbl_model_feed_final[net_revenue_retention_rate],tbl_model_feed_final[reporting_month_date],C$4),"") -> 0.99987679 | D15: =IF(D$5="Actual",SUMIFS(tbl_model_feed_final[net_revenue_retention_rate],tbl_model_feed_final[reporting_month_date],D$4),"") -> 0.99986557 | E15: =IF(E$5="Actual",SUMIFS(tbl_model_feed_final[net_revenue_retention_rate],tbl_model_feed_final[reporting_month_date],E$4),"") -> 0.999804 | F15: =IF(F$5="Actual",SUMIFS(tbl_model_feed_final[net_revenue_retention_rate],tbl_model_feed_final[reporting_month_date],F$4),"") -> 1.0003179 | G15: =IF(G$5="Actual",SUMIFS(tbl_model_feed_final[net_revenue_retention_rate],tbl_model_feed_final[reporting_month_date],G$4),"") -> 1.0007459 | H15: =IF(H$5="Actual",SUMIFS(tbl_model_feed_final[net_revenue_retention_rate],tbl_model_feed_final[reporting_month_date],H$4),"") -> 1.0009787 | I15: =IF(I$5="Actual",SUMIFS(tbl_model_feed_final[net_revenue_retention_rate],tbl_model_feed_final[reporting_month_date],I$4),"") -> 0.99881498 | ... AQ15: =IF(AQ$5="Actual",SUMIFS(tbl_model_feed_final[net_revenue_retention_rate],tbl_model_feed_final[reporting_month_date],AQ$4),"") -> 0.97478588 | AR15: =IF(AR$5="Actual",SUMIFS(tbl_model_feed_final[net_revenue_retention_rate],tbl_model_feed_final[reporting_month_date],AR$4),_xlfn.XLOOKUP("NRR",tbl_assumptions[Driver],tbl_assumptions[Selected Scenario])) -> 1.04 | AS15: =IF(AS$5="Actual",SUMIFS(tbl_model_feed_final[net_revenue_retention_rate],tbl_model_feed_final[reporting_month_date],AS$4),_xlfn.XLOOKUP("NRR",tbl_assumptions[Driver],tbl_assumptions[Selected Scenario])) -> 1.04 | AT15: =IF(AT$5="Actual",SUMIFS(tbl_model_feed_final[net_revenue_retention_rate],tbl_model_feed_final[reporting_month_date],AT$4),_xlfn.XLOOKUP("NRR",tbl_assumptions[Driver],tbl_assumptions[Selected Scenario])) -> 1.04 | AU15: =IF(AU$5="Actual",SUMIFS(tbl_model_feed_final[net_revenue_retention_rate],tbl_model_feed_final[reporting_month_date],AU$4),_xlfn.XLOOKUP("NRR",tbl_assumptions[Driver],tbl_assumptions[Selected Scenario])) -> 1.04 | AV15: =IF(AV$5="Actual",SUMIFS(tbl_model_feed_final[net_revenue_retention_rate],tbl_model_feed_final[reporting_month_date],AV$4),_xlfn.XLOOKUP("NRR",tbl_assumptions[Driver],tbl_assumptions[Selected Scenario])) -> 1.04 | AW15: =IF(AW$5="Actual",SUMIFS(tbl_model_feed_final[net_revenue_retention_rate],tbl_model_feed_final[reporting_month_date],AW$4),_xlfn.XLOOKUP("NRR",tbl_assumptions[Driver],tbl_assumptions[Selected Scenario])) -> 1.04 | AX15: =IF(AX$5="Actual",SUMIFS(tbl_model_feed_final[net_revenue_retention_rate],tbl_model_feed_final[reporting_month_date],AX$4),_xlfn.XLOOKUP("NRR",tbl_assumptions[Driver],tbl_assumptions[Selected Scenario])) -> 1.04 | AY15: =IF(AY$5="Actual",SUMIFS(tbl_model_feed_final[net_revenue_retention_rate],tbl_model_feed_final[reporting_month_date],AY$4),_xlfn.XLOOKUP("NRR",tbl_assumptions[Driver],tbl_assumptions[Selected Scenario])) -> 1.04 | ... CG15: =IF(CG$5="Actual",SUMIFS(tbl_model_feed_final[net_revenue_retention_rate],tbl_model_feed_final[reporting_month_date],CG$4),_xlfn.XLOOKUP("NRR",tbl_assumptions[Driver],tbl_assumptions[Selected Scenario])) -> 1.04
A16: Logo Churn | B16: =IF(B$5="Actual",SUMIFS(tbl_model_feed_final[logo_churn_rate],tbl_model_feed_final[reporting_month_date],B$4),"") -> 0.00043994721 | C16: =IF(C$5="Actual",SUMIFS(tbl_model_feed_final[logo_churn_rate],tbl_model_feed_final[reporting_month_date],C$4),"") -> 0.00085910653 | D16: =IF(D$5="Actual",SUMIFS(tbl_model_feed_final[logo_churn_rate],tbl_model_feed_final[reporting_month_date],D$4),"") -> 0.00083927822 | E16: =IF(E$5="Actual",SUMIFS(tbl_model_feed_final[logo_churn_rate],tbl_model_feed_final[reporting_month_date],E$4),"") -> 0 | F16: =IF(F$5="Actual",SUMIFS(tbl_model_feed_final[logo_churn_rate],tbl_model_feed_final[reporting_month_date],F$4),"") -> 0.00039761431 | G16: =IF(G$5="Actual",SUMIFS(tbl_model_feed_final[logo_churn_rate],tbl_model_feed_final[reporting_month_date],G$4),"") -> 0.00038520801 | H16: =IF(H$5="Actual",SUMIFS(tbl_model_feed_final[logo_churn_rate],tbl_model_feed_final[reporting_month_date],H$4),"") -> 0 | I16: =IF(I$5="Actual",SUMIFS(tbl_model_feed_final[logo_churn_rate],tbl_model_feed_final[reporting_month_date],I$4),"") -> 0.00073855244 | ... AQ16: =IF(AQ$5="Actual",SUMIFS(tbl_model_feed_final[logo_churn_rate],tbl_model_feed_final[reporting_month_date],AQ$4),"") -> 0.0002753304 | AR16: =IF(AR$5="Actual",SUMIFS(tbl_model_feed_final[logo_churn_rate],tbl_model_feed_final[reporting_month_date],AR$4),_xlfn.XLOOKUP("Logo Churn",tbl_assumptions[Driver],tbl_assumptions[Selected Scenario])) -> 0.018 | AS16: =IF(AS$5="Actual",SUMIFS(tbl_model_feed_final[logo_churn_rate],tbl_model_feed_final[reporting_month_date],AS$4),_xlfn.XLOOKUP("Logo Churn",tbl_assumptions[Driver],tbl_assumptions[Selected Scenario])) -> 0.018 | AT16: =IF(AT$5="Actual",SUMIFS(tbl_model_feed_final[logo_churn_rate],tbl_model_feed_final[reporting_month_date],AT$4),_xlfn.XLOOKUP("Logo Churn",tbl_assumptions[Driver],tbl_assumptions[Selected Scenario])) -> 0.018 | AU16: =IF(AU$5="Actual",SUMIFS(tbl_model_feed_final[logo_churn_rate],tbl_model_feed_final[reporting_month_date],AU$4),_xlfn.XLOOKUP("Logo Churn",tbl_assumptions[Driver],tbl_assumptions[Selected Scenario])) -> 0.018 | AV16: =IF(AV$5="Actual",SUMIFS(tbl_model_feed_final[logo_churn_rate],tbl_model_feed_final[reporting_month_date],AV$4),_xlfn.XLOOKUP("Logo Churn",tbl_assumptions[Driver],tbl_assumptions[Selected Scenario])) -> 0.018 | AW16: =IF(AW$5="Actual",SUMIFS(tbl_model_feed_final[logo_churn_rate],tbl_model_feed_final[reporting_month_date],AW$4),_xlfn.XLOOKUP("Logo Churn",tbl_assumptions[Driver],tbl_assumptions[Selected Scenario])) -> 0.018 | AX16: =IF(AX$5="Actual",SUMIFS(tbl_model_feed_final[logo_churn_rate],tbl_model_feed_final[reporting_month_date],AX$4),_xlfn.XLOOKUP("Logo Churn",tbl_assumptions[Driver],tbl_assumptions[Selected Scenario])) -> 0.018 | AY16: =IF(AY$5="Actual",SUMIFS(tbl_model_feed_final[logo_churn_rate],tbl_model_feed_final[reporting_month_date],AY$4),_xlfn.XLOOKUP("Logo Churn",tbl_assumptions[Driver],tbl_assumptions[Selected Scenario])) -> 0.018 | ... CG16: =IF(CG$5="Actual",SUMIFS(tbl_model_feed_final[logo_churn_rate],tbl_model_feed_final[reporting_month_date],CG$4),_xlfn.XLOOKUP("Logo Churn",tbl_assumptions[Driver],tbl_assumptions[Selected Scenario])) -> 0.018
A18: Operating Costs
A19: Payroll Cost | B19: =IF(B$5="Actual",SUMIFS(tbl_model_feed_final[payroll_cost_gbp],tbl_model_feed_final[reporting_month_date],B$4)/'02_Control'!$B$18,"") -> 4641129.1 | C19: =IF(C$5="Actual",SUMIFS(tbl_model_feed_final[payroll_cost_gbp],tbl_model_feed_final[reporting_month_date],C$4)/'02_Control'!$B$18,"") -> 4731102.6 | D19: =IF(D$5="Actual",SUMIFS(tbl_model_feed_final[payroll_cost_gbp],tbl_model_feed_final[reporting_month_date],D$4)/'02_Control'!$B$18,"") -> 4807431.4 | E19: =IF(E$5="Actual",SUMIFS(tbl_model_feed_final[payroll_cost_gbp],tbl_model_feed_final[reporting_month_date],E$4)/'02_Control'!$B$18,"") -> 4868707.2 | F19: =IF(F$5="Actual",SUMIFS(tbl_model_feed_final[payroll_cost_gbp],tbl_model_feed_final[reporting_month_date],F$4)/'02_Control'!$B$18,"") -> 4929130.6 | G19: =IF(G$5="Actual",SUMIFS(tbl_model_feed_final[payroll_cost_gbp],tbl_model_feed_final[reporting_month_date],G$4)/'02_Control'!$B$18,"") -> 4974433.4 | H19: =IF(H$5="Actual",SUMIFS(tbl_model_feed_final[payroll_cost_gbp],tbl_model_feed_final[reporting_month_date],H$4)/'02_Control'!$B$18,"") -> 5078537 | I19: =IF(I$5="Actual",SUMIFS(tbl_model_feed_final[payroll_cost_gbp],tbl_model_feed_final[reporting_month_date],I$4)/'02_Control'!$B$18,"") -> 5101870.2 | ... AQ19: =IF(AQ$5="Actual",SUMIFS(tbl_model_feed_final[payroll_cost_gbp],tbl_model_feed_final[reporting_month_date],AQ$4)/'02_Control'!$B$18,"") -> 7655791.2 | AR19: =IF(AR$5="Actual",SUMIFS(tbl_model_feed_final[payroll_cost_gbp],tbl_model_feed_final[reporting_month_date],AR$4)/'02_Control'!$B$18,AQ19*(1+_xlfn.XLOOKUP("Payroll Growth %",tbl_assumptions[Driver],tbl_assumptions[Selected Scenario]))) -> 7732349.1 | AS19: =IF(AS$5="Actual",SUMIFS(tbl_model_feed_final[payroll_cost_gbp],tbl_model_feed_final[reporting_month_date],AS$4)/'02_Control'!$B$18,AR19*(1+_xlfn.XLOOKUP("Payroll Growth %",tbl_assumptions[Driver],tbl_assumptions[Selected Scenario]))) -> 7809672.6 | AT19: =IF(AT$5="Actual",SUMIFS(tbl_model_feed_final[payroll_cost_gbp],tbl_model_feed_final[reporting_month_date],AT$4)/'02_Control'!$B$18,AS19*(1+_xlfn.XLOOKUP("Payroll Growth %",tbl_assumptions[Driver],tbl_assumptions[Selected Scenario]))) -> 7887769.3 | AU19: =IF(AU$5="Actual",SUMIFS(tbl_model_feed_final[payroll_cost_gbp],tbl_model_feed_final[reporting_month_date],AU$4)/'02_Control'!$B$18,AT19*(1+_xlfn.XLOOKUP("Payroll Growth %",tbl_assumptions[Driver],tbl_assumptions[Selected Scenario]))) -> 7966647 | AV19: =IF(AV$5="Actual",SUMIFS(tbl_model_feed_final[payroll_cost_gbp],tbl_model_feed_final[reporting_month_date],AV$4)/'02_Control'!$B$18,AU19*(1+_xlfn.XLOOKUP("Payroll Growth %",tbl_assumptions[Driver],tbl_assumptions[Selected Scenario]))) -> 8046313.5 | AW19: =IF(AW$5="Actual",SUMIFS(tbl_model_feed_final[payroll_cost_gbp],tbl_model_feed_final[reporting_month_date],AW$4)/'02_Control'!$B$18,AV19*(1+_xlfn.XLOOKUP("Payroll Growth %",tbl_assumptions[Driver],tbl_assumptions[Selected Scenario]))) -> 8126776.6 | AX19: =IF(AX$5="Actual",SUMIFS(tbl_model_feed_final[payroll_cost_gbp],tbl_model_feed_final[reporting_month_date],AX$4)/'02_Control'!$B$18,AW19*(1+_xlfn.XLOOKUP("Payroll Growth %",tbl_assumptions[Driver],tbl_assumptions[Selected Scenario]))) -> 8208044.4 | AY19: =IF(AY$5="Actual",SUMIFS(tbl_model_feed_final[payroll_cost_gbp],tbl_model_feed_final[reporting_month_date],AY$4)/'02_Control'!$B$18,AX19*(1+_xlfn.XLOOKUP("Payroll Growth %",tbl_assumptions[Driver],tbl_assumptions[Selected Scenario]))) -> 8290124.8 | ... CG19: =IF(CG$5="Actual",SUMIFS(tbl_model_feed_final[payroll_cost_gbp],tbl_model_feed_final[reporting_month_date],CG$4)/'02_Control'!$B$18,CF19*(1+_xlfn.XLOOKUP("Payroll Growth %",tbl_assumptions[Driver],tbl_assumptions[Selected Scenario]))) -> 11627538
A20: AP Invoice Spend | B20: =IF(B$5="Actual",SUMIFS(tbl_model_feed_final[ap_invoice_spend_gbp],tbl_model_feed_final[reporting_month_date],B$4)/'02_Control'!$B$18,"") -> 291150.19 | C20: =IF(C$5="Actual",SUMIFS(tbl_model_feed_final[ap_invoice_spend_gbp],tbl_model_feed_final[reporting_month_date],C$4)/'02_Control'!$B$18,"") -> 658218.22 | D20: =IF(D$5="Actual",SUMIFS(tbl_model_feed_final[ap_invoice_spend_gbp],tbl_model_feed_final[reporting_month_date],D$4)/'02_Control'!$B$18,"") -> 560331.15 | E20: =IF(E$5="Actual",SUMIFS(tbl_model_feed_final[ap_invoice_spend_gbp],tbl_model_feed_final[reporting_month_date],E$4)/'02_Control'!$B$18,"") -> 755499.01 | F20: =IF(F$5="Actual",SUMIFS(tbl_model_feed_final[ap_invoice_spend_gbp],tbl_model_feed_final[reporting_month_date],F$4)/'02_Control'!$B$18,"") -> 519926.93 | G20: =IF(G$5="Actual",SUMIFS(tbl_model_feed_final[ap_invoice_spend_gbp],tbl_model_feed_final[reporting_month_date],G$4)/'02_Control'!$B$18,"") -> 679161.62 | H20: =IF(H$5="Actual",SUMIFS(tbl_model_feed_final[ap_invoice_spend_gbp],tbl_model_feed_final[reporting_month_date],H$4)/'02_Control'!$B$18,"") -> 588706.85 | I20: =IF(I$5="Actual",SUMIFS(tbl_model_feed_final[ap_invoice_spend_gbp],tbl_model_feed_final[reporting_month_date],I$4)/'02_Control'!$B$18,"") -> 863983.56 | ... AQ20: =IF(AQ$5="Actual",SUMIFS(tbl_model_feed_final[ap_invoice_spend_gbp],tbl_model_feed_final[reporting_month_date],AQ$4)/'02_Control'!$B$18,"") -> 77774.25 | AR20: =IF(AR$5="Actual",SUMIFS(tbl_model_feed_final[ap_invoice_spend_gbp],tbl_model_feed_final[reporting_month_date],AR$4)/'02_Control'!$B$18,AQ20*(1+_xlfn.XLOOKUP("AP Spend Growth %",tbl_assumptions[Driver],tbl_assumptions[Selected Scenario]))) -> 78396.444 | AS20: =IF(AS$5="Actual",SUMIFS(tbl_model_feed_final[ap_invoice_spend_gbp],tbl_model_feed_final[reporting_month_date],AS$4)/'02_Control'!$B$18,AR20*(1+_xlfn.XLOOKUP("AP Spend Growth %",tbl_assumptions[Driver],tbl_assumptions[Selected Scenario]))) -> 79023.616 | AT20: =IF(AT$5="Actual",SUMIFS(tbl_model_feed_final[ap_invoice_spend_gbp],tbl_model_feed_final[reporting_month_date],AT$4)/'02_Control'!$B$18,AS20*(1+_xlfn.XLOOKUP("AP Spend Growth %",tbl_assumptions[Driver],tbl_assumptions[Selected Scenario]))) -> 79655.804 | AU20: =IF(AU$5="Actual",SUMIFS(tbl_model_feed_final[ap_invoice_spend_gbp],tbl_model_feed_final[reporting_month_date],AU$4)/'02_Control'!$B$18,AT20*(1+_xlfn.XLOOKUP("AP Spend Growth %",tbl_assumptions[Driver],tbl_assumptions[Selected Scenario]))) -> 80293.051 | AV20: =IF(AV$5="Actual",SUMIFS(tbl_model_feed_final[ap_invoice_spend_gbp],tbl_model_feed_final[reporting_month_date],AV$4)/'02_Control'!$B$18,AU20*(1+_xlfn.XLOOKUP("AP Spend Growth %",tbl_assumptions[Driver],tbl_assumptions[Selected Scenario]))) -> 80935.395 | AW20: =IF(AW$5="Actual",SUMIFS(tbl_model_feed_final[ap_invoice_spend_gbp],tbl_model_feed_final[reporting_month_date],AW$4)/'02_Control'!$B$18,AV20*(1+_xlfn.XLOOKUP("AP Spend Growth %",tbl_assumptions[Driver],tbl_assumptions[Selected Scenario]))) -> 81582.878 | AX20: =IF(AX$5="Actual",SUMIFS(tbl_model_feed_final[ap_invoice_spend_gbp],tbl_model_feed_final[reporting_month_date],AX$4)/'02_Control'!$B$18,AW20*(1+_xlfn.XLOOKUP("AP Spend Growth %",tbl_assumptions[Driver],tbl_assumptions[Selected Scenario]))) -> 82235.542 | AY20: =IF(AY$5="Actual",SUMIFS(tbl_model_feed_final[ap_invoice_spend_gbp],tbl_model_feed_final[reporting_month_date],AY$4)/'02_Control'!$B$18,AX20*(1+_xlfn.XLOOKUP("AP Spend Growth %",tbl_assumptions[Driver],tbl_assumptions[Selected Scenario]))) -> 82893.426 | ... CG20: =IF(CG$5="Actual",SUMIFS(tbl_model_feed_final[ap_invoice_spend_gbp],tbl_model_feed_final[reporting_month_date],CG$4)/'02_Control'!$B$18,CF20*(1+_xlfn.XLOOKUP("AP Spend Growth %",tbl_assumptions[Driver],tbl_assumptions[Selected Scenario]))) -> 108687.14
A21: Operating Expense Proxy | B21: =IF(B$5="Actual",SUMIFS(tbl_model_feed_final[actual_operating_expense_gbp],tbl_model_feed_final[reporting_month_date],B$4)/'02_Control'!$B$18,"") -> 4932279.3 | C21: =IF(C$5="Actual",SUMIFS(tbl_model_feed_final[actual_operating_expense_gbp],tbl_model_feed_final[reporting_month_date],C$4)/'02_Control'!$B$18,"") -> 5389320.9 | D21: =IF(D$5="Actual",SUMIFS(tbl_model_feed_final[actual_operating_expense_gbp],tbl_model_feed_final[reporting_month_date],D$4)/'02_Control'!$B$18,"") -> 5367762.6 | E21: =IF(E$5="Actual",SUMIFS(tbl_model_feed_final[actual_operating_expense_gbp],tbl_model_feed_final[reporting_month_date],E$4)/'02_Control'!$B$18,"") -> 5624206.2 | F21: =IF(F$5="Actual",SUMIFS(tbl_model_feed_final[actual_operating_expense_gbp],tbl_model_feed_final[reporting_month_date],F$4)/'02_Control'!$B$18,"") -> 5449057.5 | G21: =IF(G$5="Actual",SUMIFS(tbl_model_feed_final[actual_operating_expense_gbp],tbl_model_feed_final[reporting_month_date],G$4)/'02_Control'!$B$18,"") -> 5653595 | H21: =IF(H$5="Actual",SUMIFS(tbl_model_feed_final[actual_operating_expense_gbp],tbl_model_feed_final[reporting_month_date],H$4)/'02_Control'!$B$18,"") -> 5667243.8 | I21: =IF(I$5="Actual",SUMIFS(tbl_model_feed_final[actual_operating_expense_gbp],tbl_model_feed_final[reporting_month_date],I$4)/'02_Control'!$B$18,"") -> 5965853.7 | ... AQ21: =IF(AQ$5="Actual",SUMIFS(tbl_model_feed_final[actual_operating_expense_gbp],tbl_model_feed_final[reporting_month_date],AQ$4)/'02_Control'!$B$18,"") -> 7733565.4 | AR21: =IF(AR$5="Actual",SUMIFS(tbl_model_feed_final[actual_operating_expense_gbp],tbl_model_feed_final[reporting_month_date],AR$4)/'02_Control'!$B$18,AR19+AR20) -> 7810745.5 | AS21: =IF(AS$5="Actual",SUMIFS(tbl_model_feed_final[actual_operating_expense_gbp],tbl_model_feed_final[reporting_month_date],AS$4)/'02_Control'!$B$18,AS19+AS20) -> 7888696.2 | AT21: =IF(AT$5="Actual",SUMIFS(tbl_model_feed_final[actual_operating_expense_gbp],tbl_model_feed_final[reporting_month_date],AT$4)/'02_Control'!$B$18,AT19+AT20) -> 7967425.1 | AU21: =IF(AU$5="Actual",SUMIFS(tbl_model_feed_final[actual_operating_expense_gbp],tbl_model_feed_final[reporting_month_date],AU$4)/'02_Control'!$B$18,AU19+AU20) -> 8046940.1 | AV21: =IF(AV$5="Actual",SUMIFS(tbl_model_feed_final[actual_operating_expense_gbp],tbl_model_feed_final[reporting_month_date],AV$4)/'02_Control'!$B$18,AV19+AV20) -> 8127248.9 | AW21: =IF(AW$5="Actual",SUMIFS(tbl_model_feed_final[actual_operating_expense_gbp],tbl_model_feed_final[reporting_month_date],AW$4)/'02_Control'!$B$18,AW19+AW20) -> 8208359.5 | AX21: =IF(AX$5="Actual",SUMIFS(tbl_model_feed_final[actual_operating_expense_gbp],tbl_model_feed_final[reporting_month_date],AX$4)/'02_Control'!$B$18,AX19+AX20) -> 8290279.9 | AY21: =IF(AY$5="Actual",SUMIFS(tbl_model_feed_final[actual_operating_expense_gbp],tbl_model_feed_final[reporting_month_date],AY$4)/'02_Control'!$B$18,AY19+AY20) -> 8373018.2 | ... CG21: =IF(CG$5="Actual",SUMIFS(tbl_model_feed_final[actual_operating_expense_gbp],tbl_model_feed_final[reporting_month_date],CG$4)/'02_Control'!$B$18,CG19+CG20) -> 11736225
A22: Operating expense proxy check | B22: =IF(B$5="Actual",B19+B20-B21,0) -> 0 | C22: =IF(C$5="Actual",C19+C20-C21,0) -> 0 | D22: =IF(D$5="Actual",D19+D20-D21,0) -> 0 | E22: =IF(E$5="Actual",E19+E20-E21,0) -> 0 | F22: =IF(F$5="Actual",F19+F20-F21,0) -> 0 | G22: =IF(G$5="Actual",G19+G20-G21,0) -> 0 | H22: =IF(H$5="Actual",H19+H20-H21,0) -> 0 | I22: =IF(I$5="Actual",I19+I20-I21,0) -> 0 | ... AQ22: =IF(AQ$5="Actual",AQ19+AQ20-AQ21,0) -> 0 | AR22: =IF(AQ$5="Actual",AQ19+AQ20-AQ21,0) -> 0 | AS22: =IF(AR$5="Actual",AR19+AR20-AR21,0) -> 0 | AT22: =IF(AS$5="Actual",AS19+AS20-AS21,0) -> 0 | AU22: =IF(AT$5="Actual",AT19+AT20-AT21,0) -> 0 | AV22: =IF(AU$5="Actual",AU19+AU20-AU21,0) -> 0 | AW22: =IF(AV$5="Actual",AV19+AV20-AV21,0) -> 0 | AX22: =IF(AW$5="Actual",AW19+AW20-AW21,0) -> 0 | AY22: =IF(AX$5="Actual",AX19+AX20-AX21,0) -> 0 | ... CG22: =IF(CF$5="Actual",CF19+CF20-CF21,0) -> 0
A23: Operating Profit | B23: =IF(B$5="Actual",SUMIFS(tbl_model_feed_final[actual_operating_profit_gbp],tbl_model_feed_final[reporting_month_date],B$4)/'02_Control'!$B$18,"") -> -3465652.9 | C23: =IF(C$5="Actual",SUMIFS(tbl_model_feed_final[actual_operating_profit_gbp],tbl_model_feed_final[reporting_month_date],C$4)/'02_Control'!$B$18,"") -> -3747605.9 | D23: =IF(D$5="Actual",SUMIFS(tbl_model_feed_final[actual_operating_profit_gbp],tbl_model_feed_final[reporting_month_date],D$4)/'02_Control'!$B$18,"") -> -3450043.9 | E23: =IF(E$5="Actual",SUMIFS(tbl_model_feed_final[actual_operating_profit_gbp],tbl_model_feed_final[reporting_month_date],E$4)/'02_Control'!$B$18,"") -> -3501321.5 | F23: =IF(F$5="Actual",SUMIFS(tbl_model_feed_final[actual_operating_profit_gbp],tbl_model_feed_final[reporting_month_date],F$4)/'02_Control'!$B$18,"") -> -3075286.5 | G23: =IF(G$5="Actual",SUMIFS(tbl_model_feed_final[actual_operating_profit_gbp],tbl_model_feed_final[reporting_month_date],G$4)/'02_Control'!$B$18,"") -> -3029531.5 | H23: =IF(H$5="Actual",SUMIFS(tbl_model_feed_final[actual_operating_profit_gbp],tbl_model_feed_final[reporting_month_date],H$4)/'02_Control'!$B$18,"") -> -2767881 | I23: =IF(I$5="Actual",SUMIFS(tbl_model_feed_final[actual_operating_profit_gbp],tbl_model_feed_final[reporting_month_date],I$4)/'02_Control'!$B$18,"") -> -2802651.1 | ... AQ23: =IF(AQ$5="Actual",SUMIFS(tbl_model_feed_final[actual_operating_profit_gbp],tbl_model_feed_final[reporting_month_date],AQ$4)/'02_Control'!$B$18,"") -> -1936177.6 | AR23: =IF(AR$5="Actual",SUMIFS(tbl_model_feed_final[actual_operating_profit_gbp],tbl_model_feed_final[reporting_month_date],AR$4)/'02_Control'!$B$18,AR10-AR21) -> -1955383.8 | AS23: =IF(AS$5="Actual",SUMIFS(tbl_model_feed_final[actual_operating_profit_gbp],tbl_model_feed_final[reporting_month_date],AS$4)/'02_Control'!$B$18,AS10-AS21) -> -1974780.8 | AT23: =IF(AT$5="Actual",SUMIFS(tbl_model_feed_final[actual_operating_profit_gbp],tbl_model_feed_final[reporting_month_date],AT$4)/'02_Control'!$B$18,AT10-AT21) -> -1994370.6 | AU23: =IF(AU$5="Actual",SUMIFS(tbl_model_feed_final[actual_operating_profit_gbp],tbl_model_feed_final[reporting_month_date],AU$4)/'02_Control'!$B$18,AU10-AU21) -> -2014155 | AV23: =IF(AV$5="Actual",SUMIFS(tbl_model_feed_final[actual_operating_profit_gbp],tbl_model_feed_final[reporting_month_date],AV$4)/'02_Control'!$B$18,AV10-AV21) -> -2034136 | AW23: =IF(AW$5="Actual",SUMIFS(tbl_model_feed_final[actual_operating_profit_gbp],tbl_model_feed_final[reporting_month_date],AW$4)/'02_Control'!$B$18,AW10-AW21) -> -2054315.5 | AX23: =IF(AX$5="Actual",SUMIFS(tbl_model_feed_final[actual_operating_profit_gbp],tbl_model_feed_final[reporting_month_date],AX$4)/'02_Control'!$B$18,AX10-AX21) -> -2074695.4 | AY23: =IF(AY$5="Actual",SUMIFS(tbl_model_feed_final[actual_operating_profit_gbp],tbl_model_feed_final[reporting_month_date],AY$4)/'02_Control'!$B$18,AY10-AY21) -> -2095277.9 | ... CG23: =IF(CG$5="Actual",SUMIFS(tbl_model_feed_final[actual_operating_profit_gbp],tbl_model_feed_final[reporting_month_date],CG$4)/'02_Control'!$B$18,CG10-CG21) -> -2931211.3
A24: Operating Profit Check | B24: =IF(B$5="Actual",B10-B21-B23,0) -> 0 | C24: =IF(C$5="Actual",C10-C21-C23,0) -> 0 | D24: =IF(D$5="Actual",D10-D21-D23,0) -> 0 | E24: =IF(E$5="Actual",E10-E21-E23,0) -> 0 | F24: =IF(F$5="Actual",F10-F21-F23,0) -> 0 | G24: =IF(G$5="Actual",G10-G21-G23,0) -> 0 | H24: =IF(H$5="Actual",H10-H21-H23,0) -> 0 | I24: =IF(I$5="Actual",I10-I21-I23,0) -> 0 | ... CG24: =IF(CG$5="Actual",CG10-CG21-CG23,0) -> 0
A25: Operating Margin | B25: =IF(B$5="Actual",SUMIFS(tbl_model_feed_final[actual_operating_margin],tbl_model_feed_final[reporting_month_date],B$4),"") -> -2.36301 | C25: =IF(C$5="Actual",SUMIFS(tbl_model_feed_final[actual_operating_margin],tbl_model_feed_final[reporting_month_date],C$4),"") -> -2.2827385 | D25: =IF(D$5="Actual",SUMIFS(tbl_model_feed_final[actual_operating_margin],tbl_model_feed_final[reporting_month_date],D$4),"") -> -1.7990355 | E25: =IF(E$5="Actual",SUMIFS(tbl_model_feed_final[actual_operating_margin],tbl_model_feed_final[reporting_month_date],E$4),"") -> -1.6493225 | F25: =IF(F$5="Actual",SUMIFS(tbl_model_feed_final[actual_operating_margin],tbl_model_feed_final[reporting_month_date],F$4),"") -> -1.2955279 | G25: =IF(G$5="Actual",SUMIFS(tbl_model_feed_final[actual_operating_margin],tbl_model_feed_final[reporting_month_date],G$4),"") -> -1.1545191 | H25: =IF(H$5="Actual",SUMIFS(tbl_model_feed_final[actual_operating_margin],tbl_model_feed_final[reporting_month_date],H$4),"") -> -0.95465151 | I25: =IF(I$5="Actual",SUMIFS(tbl_model_feed_final[actual_operating_margin],tbl_model_feed_final[reporting_month_date],I$4),"") -> -0.88601695 | ... AQ25: =IF(AQ$5="Actual",SUMIFS(tbl_model_feed_final[actual_operating_margin],tbl_model_feed_final[reporting_month_date],AQ$4),"") -> -0.33397413 | AR25: =IFERROR(AR23/AR10,"") -> -0.33394757 | AS25: =IFERROR(AS23/AS10,"") -> -0.33392105 | AT25: =IFERROR(AT23/AT10,"") -> -0.33389459 | AU25: =IFERROR(AU23/AU10,"") -> -0.33386819 | AV25: =IFERROR(AV23/AV10,"") -> -0.33384183 | AW25: =IFERROR(AW23/AW10,"") -> -0.33381553 | AX25: =IFERROR(AX23/AX10,"") -> -0.33378928 | AY25: =IFERROR(AY23/AY10,"") -> -0.33376308 | ... CG25: =IFERROR(CG23/CG10,"") -> -0.33290251
